Workbook

Sheet Лист7
A1: наименование | B1: Менеджер | C1: Схема продажи | D1: ЕДИНЫЙ АРТИКУЛ | E1: Кратность на паллете | F1: Артикул МФП | G1: WB МФП | H1: WB ЛЕТТА | I1: WB МАЙЛЕТТА | J1: WB Емебель | K1: Артикул OZON МФП | L1: FBO OZON SKU ID МФП | M1: FBS OZON SKU ID МФП | N1: Артикул OZON ЛЕТТА | O1: FBO OZON SKU ID ЛЕТТА | P1: FBS OZON SKU ID ЛЕТТА | Q1: Артикул OZON МАЙЛЕТТА | R1: FBO OZON SKU ID МАЙЛЕТТА | S1: FBS OZON SKU ID МАЙЛЕТТА | T1: Артикул OZON ЕМебель | U1: FBO OZON SKU ID ЕМебель | V1: FBS OZON SKU ID Емебель | W1: Яндексмаркет МФП | X1: Яндексмаркет ЛЕТТА | Y1: СБЕРМЕГАМАРКЕТ | AA1: Статус позиции | AB1: Категория | AC1: ЕДИНЫЙ АРТИКУЛ | AD1: Схема продажи
A2: ВЕШАЛКИ | B2: Кошкарева | AA2: =IFERROR(VLOOKUP(D:D,[1]Габариты!$A:$I,9,0),"") | AB2: =IFERROR(VLOOKUP(D:D,[1]Габариты!$A:$D,4,0),"")
A3: Вешалка выкатная Ultra с полками Белое тиснение | C3: FBS | D3: 3153 | E3: 19 | F3: 3153 | G3: 4660041004663 | H3: 2521897952400 | I3: 3521897952400 | J3: 5000897952636 | K3: 03153 | L3: 387822438 | M3: 387822438 | N3: L3153 | O3: 379766050 | P3: 379766049 | Q3: ML3153 | R3: 379871679 | S3: 379871680 | W3: 03153 | X3: L3153 | Y3: 3153 | AA3: =IFERROR(VLOOKUP(D:D,[1]Габариты!$A:$I,9,0),"") -> Основной ассортимент | AB3: =IFERROR(VLOOKUP(D:D,[1]Габариты!$A:$D,4,0),"") -> ВЕШАЛКИ | AC3: =D3 -> 3153 | AD3: =C3 -> FBS
A4: Вешалка выкатная Ultra с полками Дуб Сонома 786х1463(h)х250 | C4: FBS | D4: 3355 | E4: 19 | F4: 3355 | G4: 4660041005301 | H4: 2521897952528 | I4: 3521897952650 | J4: 5000897952643 | K4: 03355 | L4: 1842339541 | M4: 1842339541 | N4: L3355 | O4: 518641075 | P4: 518641077 | W4: 03355 | X4: L3355 | Y4: 3355 | AA4: =IFERROR(VLOOKUP(D:D,[1]Габариты!$A:$I,9,0),"") -> Основной ассортимент | AB4: =IFERROR(VLOOKUP(D:D,[1]Габариты!$A:$D,4,0),"") -> ВЕШАЛКИ | AC4: =D4 -> 3355 | AD4: =C4 -> FBS
A5: Вешалка выкатная Ultra с полками Черная 786х1463(h)х250 | C5: FBS | D5: 3356 | E5: 19 | F5: 3356 | G5: 4660041005318 | H5: 2521897952530 | I5: 3521897952530 | J5: 5000897952644 | K5: 03356 | L5: 1431518467 | M5: 1431518467 | N5: L3356 | O5: 520590680 | P5: 520590677 | W5: 03356 | X5: L3356 | Y5: 3356 | AA5: =IFERROR(VLOOKUP(D:D,[1]Габариты!$A:$I,9,0),"") -> Основной ассортимент | AB5: =IFERROR(VLOOKUP(D:D,[1]Габариты!$A:$D,4,0),"") -> ВЕШАЛКИ | AC5: =D5 -> 3356 | AD5: =C5 -> FBS
A6: Вешалка настенная Ультра Белое тиснение 0,600 х1,050х0,282 | C6: FBS | D6: 30361 | E6: 34 | H6: 2521897952567 | J6: 5520897927564 | N6: L30361 | O6: 608852540 | P6: 608852539 | T6: E30361 | U6: 1341121105 | V6: 1341121105 | X6: L30361 | Y6: 30361 | AA6: =IFERROR(VLOOKUP(D:D,[1]Габариты!$A:$I,9,0),"") -> Основной ассортимент | AB6: =IFERROR(VLOOKUP(D:D,[1]Габариты!$A:$D,4,0),"") -> ВЕШАЛКИ | AC6: =D6 -> 30361 | AD6: =C6 -> FBS
A7: Вешалка настенная Ультра Дуб сонома 0,600 х1,050х0,282 | C7: FBS | D7: 30362 | E7: 34 | H7: 2521897952568 | J7: 5520897927565 | N7: L30362 | O7: 617937053 | P7: 617937054 | T7: E30362 | U7: 1341126586 | V7: 1341126586 | X7: L30362 | Y7: 30362 | AA7: =IFERROR(VLOOKUP(D:D,[1]Габариты!$A:$I,9,0),"") -> Основной ассортимент | AB7: =IFERROR(VLOOKUP(D:D,[1]Габариты!$A:$D,4,0),"") -> ВЕШАЛКИ | AC7: =D7 -> 30362 | AD7: =C7 -> FBS
A8: Вешалка настенная Ультра Венге 0,600 х1,050х0,282 | C8: FBS | D8: 30363 | E8: 34 | H8: 2521897952569 | J8: 5520897927386 | N8: L30363 | O8: 617987616 | P8: 617987620 | T8: E30363 | U8: 1341136272 | V8: 1341136272 | X8: L30363 | Y8: 30363 | AA8: =IFERROR(VLOOKUP(D:D,[1]Габариты!$A:$I,9,0),"") -> Основной ассортимент | AB8: =IFERROR(VLOOKUP(D:D,[1]Габариты!$A:$D,4,0),"") -> ВЕШАЛКИ | AC8: =D8 -> 30363 | AD8: =C8 -> FBS
A9: Вешалка Милан настенная Белое тиснение | C9: FBO | D9: 30364 | E9: 56 | H9: 2521897953028 | I9: 3521897952663 | J9: 5520897927431 | N9: L30364 | O9: 983504437 | P9: 983504436 | Q9: ML30364 | R9: 983929528 | S9: 983929527 | T9: E30364 | U9: 983897205 | V9: 983897205 | X9: L30364 | AA9: =IFERROR(VLOOKUP(D:D,[1]Габариты!$A:$I,9,0),"") -> Основной ассортимент | AB9: =IFERROR(VLOOKUP(D:D,[1]Габариты!$A:$D,4,0),"") -> ВЕШАЛКИ | AC9: =D9 -> 30364 | AD9: =C9 -> FBO
A10: Вешалка Милан настенная Крафт золотой/графит | C10: FBO | D10: 30365 | E10: 56 | H10: 2521897953029 | I10: 3521897952664 | J10: 5520897927432 | N10: L30365 | O10: 983528480 | P10: 983528479 | Q10: ML30365 | R10: 983939704 | S10: 983939704 | T10: E30365 | U10: 983908029 | V10: 983908029 | X10: L30365 | Y10: 30365 | AA10: =IFERROR(VLOOKUP(D:D,[1]Габариты!$A:$I,9,0),"") -> Основной ассортимент | AB10: =IFERROR(VLOOKUP(D:D,[1]Габариты!$A:$D,4,0),"") -> ВЕШАЛКИ | AC10: =D10 -> 30365 | AD10: =C10 -> FBO
A11: Вешалка Милан настенная Крафт золотой/Белое тиснение | C11: FBO | D11: 30366 | E11: 56 | H11: 2521897953030 | I11: 3521897952665 | J11: 5520897927433 | N11: L30366 | O11: 983535347 | P11: 983535348 | Q11: ML30366 | R11: 983950283 | S11: 983950283 | T11: E30366 | U11: 983915077 | V11: 983915077 | X11: L30366 | Y11: 30366 | AA11: =IFERROR(VLOOKUP(D:D,[1]Габариты!$A:$I,9,0),"") -> Основной ассортимент | AB11: =IFERROR(VLOOKUP(D:D,[1]Габариты!$A:$D,4,0),"") -> ВЕШАЛКИ | AC11: =D11 -> 30366 | AD11: =C11 -> FBO
A12: Вешалка Милан настенная Бетон/Белое тиснение | C12: FBO | D12: 30367 | E12: 56 | H12: 2521897953031 | I12: 3521897952666 | J12: 5520897927434 | N12: L30367 | O12: 983544102 | P12: 983544103 | Q12: ML30367 | R12: 983961580 | S12: 983961579 | T12: E30367 | U12: 983920551 | V12: 983920551 | X12: L30367 | Y12: 30367 | AA12: =IFERROR(VLOOKUP(D:D,[1]Габариты!$A:$I,9,0),"") -> Основной ассортимент | AB12: =IFERROR(VLOOKUP(D:D,[1]Габариты!$A:$D,4,0),"") -> ВЕШАЛКИ | AC12: =D12 -> 30367 | AD12: =C12 -> FBO
A13: Вешалка Милан настенная Крафт табачный | C13: FBO | D13: 30368 | E13: 56 | H13: 2521897953057 | I13: 3521897952683 | J13: 5520897927484 | N13: L30368 | O13: 1004344667 | P13: 1004344666 | Q13: ML30368 | R13: 1020335184 | S13: 1020335184 | T13: E30368 | U13: 1020289773 | V13: 1020289773 | X13: L30368 | AA13: =IFERROR(VLOOKUP(D:D,[1]Габариты!$A:$I,9,0),"") -> Основной ассортимент | AB13: =IFERROR(VLOOKUP(D:D,[1]Габариты!$A:$D,4,0),"") -> ВЕШАЛКИ | AC13: =D13 -> 30368 | AD13: =C13 -> FBO
A14: Вешалка Frame ЛДСП Дуб Вотан, Черн. металл. 802х1750(h)х278 | C14: FBS | D14: MK1370101 | E14: 26 | F14: МК.137.01.01 | G14: 4660041006902 | H14: 2521897952732 | J14: 5000897952642 | K14: МК.137.01.01 | L14: 1361820562 | M14: 1361820562 | N14: LMK1370101 | O14: 733280296 | P14: 733280297 | X14: LMK1370101 | AA14: =IFERROR(VLOOKUP(D:D,[1]Габариты!$A:$I,9,0),"") -> Основной ассортимент | AB14: =IFERROR(VLOOKUP(D:D,[1]Габариты!$A:$D,4,0),"") -> ВЕШАЛКИ | AC14: =D14 -> MK1370101 | AD14: =C14 -> FBS
A15: Вешалка Frame ЛДСП Белое тиснение, Черн. металл. 802х1750(h)х278 | C15: FBS | D15: MK1370201 | E15: 26 | F15: МК.137.02.01 | G15: 4660041006919 | H15: 2521897952733 | K15: МК.137.02.01 | L15: 1378174624 | M15: 1378174624 | N15: LMK1370201 | X15: LMK1370201 | AA15: =IFERROR(VLOOKUP(D:D,[1]Габариты!$A:$I,9,0),"") -> Основной ассортимент | AB15: =IFERROR(VLOOKUP(D:D,[1]Габариты!$A:$D,4,0),"") -> ВЕШАЛКИ | AC15: =D15 -> MK1370201 | AD15: =C15 -> FBS
A16: Вешалка угловая Frame ЛДСП Дуб Вотан, Черн. металл. 490х1808(h)х490 | C16: FBO | D16: MK2170101 | E16: 26 | F16: МК.217.01.01 | G16: 4660041008296 | H16: 4660041008296 | K16: МК.217.01.01 | L16: 1284359767 | M16: 1284359767 | N16: LMK2170101 | X16: LMK2170101 | AA16: =IFERROR(VLOOKUP(D:D,[1]Габариты!$A:$I,9,0),"") -> Основной ассортимент | AB16: =IFERROR(VLOOKUP(D:D,[1]Габариты!$A:$D,4,0),"") -> ВЕШАЛКИ | AC16: =D16 -> MK2170101 | AD16: =C16 -> FBO
A17: Вешалка Frame Lite ЛДСП Дуб Вотан, Черн. металл. 780х1750(h)х278 | C17: FBO | D17: MK2470101 | E17: 36 | F17: МК.247.01.01 | G17: 4660041009354 | H17: 4660041009354 | K17: МК.247.01.01 | L17: 1316850035 | M17: 1316850035 | N17: LMK2470101 | O17: 1849368561 | P17: 1849368561 | X17: LMK2470101 | AA17: =IFERROR(VLOOKUP(D:D,[1]Габариты!$A:$I,9,0),"") -> Основной ассортимент | AB17: =IFERROR(VLOOKUP(D:D,[1]Габариты!$A:$D,4,0),"") -> ВЕШАЛКИ | AC17: =D17 -> MK2470101 | AD17: =C17 -> FBO
A18: ВЕШАЛКИ | B18: Перепечаева | AA18: =IFERROR(VLOOKUP(D:D,[1]Габариты!$A:$I,9,0),"") | AB18: =IFERROR(VLOOKUP(D:D,[1]Габариты!$A:$D,4,0),"")
A19: Вешалка в прихожую Frame с зеркалом ЛДСП Дуб Вотан, Черн.металл. 820х1813(h)х350 | C19: СКГТ (ОЗОН) | D19: MK2180101 | E19: 15 | F19: МК.218.01.01 | G19: 4660041009156 | H19: 4660041009156 | K19: МК.218.01.01 | L19: 1617713319 | M19: 1617713319 | N19: LMK2180101 | O19: 1906460228 | P19: 1906460228 | AA19: =IFERROR(VLOOKUP(D:D,[1]Габариты!$A:$I,9,0),"") -> Основной ассортимент | AB19: =IFERROR(VLOOKUP(D:D,[1]Габариты!$A:$D,4,0),"") -> ВЕШАЛКИ | AC19: =D19 -> MK2180101 | AD19: =C19 -> СКГТ (ОЗОН)
A20: Система хранения Frame №1 ЛДСП Цемент темный молет, Черн. металл.1140х1808(h)х404 | C20: СКГТ | D20: MK1612501 | E20: 10 | F20: МК.161.25.01 | G20: 4640219956536 | H20: 2521897953563 | K20: МК.161.25.01 | L20: 1781379276 | M20: 1781379276 | N20: LMK1612501 | X20: LMK1612501 | AA20: =IFERROR(VLOOKUP(D:D,[1]Габариты!$A:$I,9,0),"") -> Вакансия | AB20: =IFERROR(VLOOKUP(D:D,[1]Габариты!$A:$D,4,0),"") -> ВЕШАЛКИ | AC20: =D20 -> MK1612501 | AD20: =C20 -> СКГТ
A21: Система хранения Frame №2 ЛДСП Дуб Вотан, Черн. металл, Ткань Strong 04 902х1808(h)х408 | C21: СКГТ | D21: MK167010121 | E21: 7 | F21: МК.167.01.01.21 | G21: 4640219950374 | K21: MK167010121 | L21: 1589045509 | M21: 1589045509 | AA21: =IFERROR(VLOOKUP(D:D,[1]Габариты!$A:$I,9,0),"") -> Основной ассортимент | AB21: =IFERROR(VLOOKUP(D:D,[1]Габариты!$A:$D,4,0),"") -> ВЕШАЛКИ | AC21: =D21 -> MK167010121 | AD21: =C21 -> СКГТ
A22: Система хранения Tokyo №1 ЛДСП Дуб Вотан, Черн.металл | C22: FBO | D22: MK1690101 | E22: 10 | F22: МК.169.01.01 | G22: 4660041008302 | H22: 4660041008302 | K22: МК.169.01.01 | L22: 1284552089 | M22: 1284552089 | N22: LMK1690101 | O22: 1911237641 | P22: 1911237641 | X22: LMK1690101 | AA22: =IFERROR(VLOOKUP(D:D,[1]Габариты!$A:$I,9,0),"") -> Основной ассортимент | AB22: =IFERROR(VLOOKUP(D:D,[1]Габариты!$A:$D,4,0),"") -> ВЕШАЛКИ | AC22: =D22 -> MK1690101 | AD22: =C22 -> FBO
A23: КОМОДЫ | B23: Платонова | AA23: =IFERROR(VLOOKUP(D:D,[1]Габариты!$A:$I,9,0),"") | AB23: =IFERROR(VLOOKUP(D:D,[1]Габариты!$A:$D,4,0),"")
A24: Комод City New 6 ящиков Белое тиснение 1400*827*394 | C24: СКГТ (ОЗОН) | D24: 3750 | E24: 8 | F24: 3750 | G24: 4640219955409 | H24: 2521897953253 | J24: 5520897927609 | K24: 03750 | L24: 1841667736 | M24: 1841667736 | N24: L3750 | O24: 1463663376 | P24: 1463663376 | X24: L3750 | AA24: =IFERROR(VLOOKUP(D:D,[1]Габариты!$A:$I,9,0),"") -> Основной ассортимент | AB24: =IFERROR(VLOOKUP(D:D,[1]Габариты!$A:$D,4,0),"") -> КОМОДЫ | AC24: =D24 -> 3750 | AD24: =C24 -> СКГТ (ОЗОН)
A25: Комод City New 6 ящиков Дуб Вотан 1402*827*394 | C25: СКГТ (ОЗОН) | D25: 3750.01/01 | E25: 8 | F25: 03750.01/01 | G25: 4640219955560 | H25: 2521897953489 | K25: 03750.01/01 | L25: 1525323206 | M25: 1525323206 | N25: L3750.01/01 | O25: 1763863520 | P25: 1763863520 | X25: L3750.01/01 | AA25: =IFERROR(VLOOKUP(D:D,[1]Габариты!$A:$I,9,0),"") -> Основной ассортимент | AB25: =IFERROR(VLOOKUP(D:D,[1]Габариты!$A:$D,4,0),"") -> КОМОДЫ | AC25: =D25 -> 3750.01/01 | AD25: =C25 -> СКГТ (ОЗОН)
A26: Комод City New 6 ящиков Дуб сонома 1400*827*394 | C26: СКГТ (ОЗОН) | D26: 3750.03/01 | E26: 8 | F26: 03750.03/01 | G26: 4640219956369 | H26: 2521897953309 | K26: 03750.03/01 | L26: 1841646924 | M26: 1841646924 | N26: L3750.03/01 | O26: 1552181842 | P26: 1552181842 | X26: L3750.03/01 | Y26: 3750.03/01 | AA26: =IFERROR(VLOOKUP(D:D,[1]Габариты!$A:$I,9,0),"") -> Основной ассортимент | AB26: =IFERROR(VLOOKUP(D:D,[1]Габариты!$A:$D,4,0),"") -> КОМОДЫ | AC26: =D26 -> 3750.03/01 | AD26: =C26 -> СКГТ (ОЗОН)
A27: Комод City New 6 ящиков Дуб Крафт золотой 1402х827(h)х394 | C27: СКГТ (ОЗОН) | D27: 3750.05/01 | E27: 8 | F27: 03750.05/01 | G27: 4640219955539 | H27: 2521897953562 | K27: 03750.05/01 | L27: 1781379288 | M27: 1781379288 | N27: L3750.05/01 | O27: 1731338296 | P27: 1731338296 | X27: L3750.05/01 | AA27: =IFERROR(VLOOKUP(D:D,[1]Габариты!$A:$I,9,0),"") -> Основной ассортимент | AB27: =IFERROR(VLOOKUP(D:D,[1]Габариты!$A:$D,4,0),"") -> КОМОДЫ | AC27: =D27 -> 3750.05/01 | AD27: =C27 -> СКГТ (ОЗОН)
A28: Комод City New 6 ящиков Графит 1400*827*394 | C28: СКГТ (ОЗОН) | D28: 3750.09/01 | E28: 8 | F28: 03750.09/01 | G28: 4640219955522 | H28: 2521897953308 | K28: 03750.09/01 | L28: 1559844522 | M28: 1559844522 | N28: L3750.09/01 | O28: 1546032780 | P28: 1546032780 | X28: L3750.09/01 | Y28: 3750.09/01 | AA28: =IFERROR(VLOOKUP(D:D,[1]Габариты!$A:$I,9,0),"") -> Основной ассортимент | AB28: =IFERROR(VLOOKUP(D:D,[1]Габариты!$A:$D,4,0),"") -> КОМОДЫ | AC28: =D28 -> 3750.09/01 | AD28: =C28 -> СКГТ (ОЗОН)
A29: Комод Веста Графит 757х346х600 | C29: FBO | D29: 41101 | E29: 18 | H29: 2521897953190 | J29: 5520897927638 | N29: L41101 | O29: 1410736304 | P29: 1410736304 | T29: E41101 | U29: 1608606050 | V29: 1608606050 | X29: L41101 | AA29: =IFERROR(VLOOKUP(D:D,[1]Габариты!$A:$I,9,0),"") -> Основной ассортимент | AB29: =IFERROR(VLOOKUP(D:D,[1]Габариты!$A:$D,4,0),"") -> КОМОДЫ | AC29: =D29 -> 41101 | AD29: =C29 -> FBO
A30: Комод Веста Дуб сонома 757х346х600 | C30: FBO | D30: 41103 | E30: 18 | H30: 2521897953192 | J30: 5520897927639 | N30: L41103 | O30: 1413558701 | P30: 1413558701 | T30: E41103 | U30: 1608611824 | V30: 1608611824 | X30: L41103 | AA30: =IFERROR(VLOOKUP(D:D,[1]Габариты!$A:$I,9,0),"") -> Основной ассортимент | AB30: =IFERROR(VLOOKUP(D:D,[1]Габариты!$A:$D,4,0),"") -> КОМОДЫ | AC30: =D30 -> 41103 | AD30: =C30 -> FBO
A31: Комод Веста Дуб сонома/белое тиснение 757х346х600 | C31: FBO | D31: 41104 | E31: 18 | H31: 2521897953193 | J31: 5520897927640 | N31: L41104 | O31: 1413581472 | P31: 1413581472 | T31: E41104 | U31: 1608623053 | V31: 1608623053 | X31: L41104 | AA31: =IFERROR(VLOOKUP(D:D,[1]Габариты!$A:$I,9,0),"") -> Основной ассортимент | AB31: =IFERROR(VLOOKUP(D:D,[1]Габариты!$A:$D,4,0),"") -> КОМОДЫ | AC31: =D31 -> 41104 | AD31: =C31 -> FBO
A32: Комод Веста Венге 757х346х600 | C32: FBO | D32: 41105 | E32: 18 | H32: 2521897953194 | J32: 5520897927641 | N32: L41105 | O32: 1417302190 | P32: 1417302190 | T32: E41105 | U32: 1608632247 | V32: 1608632247 | X32: L41105 | AA32: =IFERROR(VLOOKUP(D:D,[1]Габариты!$A:$I,9,0),"") -> Основной ассортимент | AB32: =IFERROR(VLOOKUP(D:D,[1]Габариты!$A:$D,4,0),"") -> КОМОДЫ | AC32: =D32 -> 41105 | AD32: =C32 -> FBO
A33: Комод Веста Lite Белое тиснение 782х599х294 | C33: FBO | D33: 4114 | E33: 27 | H33: 2521897952982 | I33: 3521897952901 | J33: 5520897927504 | N33: L4114 | O33: 989102420 | P33: 989102419 | Q33: ML4114 | R33: 1052860791 | S33: 1052860790 | T33: E4114 | U33: 1052847785 | V33: 1052847785 | X33: L4114 | Y33: 4114 | AA33: =IFERROR(VLOOKUP(D:D,[1]Габариты!$A:$I,9,0),"") -> Основной ассортимент | AB33: =IFERROR(VLOOKUP(D:D,[1]Габариты!$A:$D,4,0),"") -> КОМОДЫ | AC33: =D33 -> 4114 | AD33: =C33 -> FBO
A34: Комод Веста Lite Графит 782х599х294 | C34: FBO | D34: 41141 | E34: 27 | H34: 2521897953183 | J34: 5520897927633 | N34: L41141 | O34: 1416718953 | P34: 1416718953 | T34: E41141 | U34: 1597560045 | V34: 1597560045 | X34: L41141 | AA34: =IFERROR(VLOOKUP(D:D,[1]Габариты!$A:$I,9,0),"") -> Основной ассортимент | AB34: =IFERROR(VLOOKUP(D:D,[1]Габариты!$A:$D,4,0),"") -> КОМОДЫ | AC34: =D34 -> 41141 | AD34: =C34 -> FBO
A35: Комод Веста Lite Дуб сонома 782х599х294 | C35: FBO | D35: 41143 | E35: 27 | H35: 2521897953185 | J35: 5520897927635 | N35: L41143 | O35: 1416722338 | P35: 1416722338 | T35: E41143 | U35: 1597591181 | V35: 1597591181 | X35: L41143 | AA35: =IFERROR(VLOOKUP(D:D,[1]Габариты!$A:$I,9,0),"") -> Основной ассортимент | AB35: =IFERROR(VLOOKUP(D:D,[1]Габариты!$A:$D,4,0),"") -> КОМОДЫ | AC35: =D35 -> 41143 | AD35: =C35 -> FBO
A36: Комод Веста Lite Дуб сонома/белое тиснение 782х599х294 | C36: FBO | D36: 41144 | E36: 27 | H36: 2521897953186 | J36: 5520897927636 | N36: L41144 | O36: 1416729517 | P36: 1416729517 | T36: E41144 | U36: 1597594093 | V36: 1597594093 | X36: L41144 | AA36: =IFERROR(VLOOKUP(D:D,[1]Габариты!$A:$I,9,0),"") -> Основной ассортимент | AB36: =IFERROR(VLOOKUP(D:D,[1]Габариты!$A:$D,4,0),"") -> КОМОДЫ | AC36: =D36 -> 41144 | AD36: =C36 -> FBO
A37: Комод Веста Lite Венге 782х599х294 | C37: FBO | D37: 41145 | E37: 27 | H37: 2521897953187 | J37: 5520897927637 | N37: L41145 | O37: 1416731164 | P37: 1416731164 | T37: E41145 | U37: 1597597442 | V37: 1597597442 | X37: L41145 | AA37: =IFERROR(VLOOKUP(D:D,[1]Габариты!$A:$I,9,0),"") -> Основной ассортимент | AB37: =IFERROR(VLOOKUP(D:D,[1]Габариты!$A:$D,4,0),"") -> КОМОДЫ | AC37: =D37 -> 41145 | AD37: =C37 -> FBO
A38: Комод Индиго (620х790х330) Белое тиснение | C38: FBO | D38: 4040 | E38: 23 | H38: 2521897953003 | I38: 3521897952659 | J38: 5520897927440 | N38: L4040 | O38: 985855939 | P38: 985855938 | Q38: ML4040 | R38: 985863116 | S38: 985863115 | T38: E4040 | U38: 985858458 | V38: 985858458 | X38: L4040 | AA38: =IFERROR(VLOOKUP(D:D,[1]Габариты!$A:$I,9,0),"") -> Основной ассортимент | AB38: =IFERROR(VLOOKUP(D:D,[1]Габариты!$A:$D,4,0),"") -> КОМОДЫ | AC38: =D38 -> 4040 | AD38: =C38 -> FBO
A39: Комод Индиго Бетон светлый | C39: FBO | D39: 4041 | E39: 23 | H39: 2521897953004 | J39: 5520897927527 | N39: L4041 | O39: 1103006728 | P39: 1103006727 | T39: E4041 | U39: 1597532535 | V39: 1597532535 | X39: L4041 | AA39: =IFERROR(VLOOKUP(D:D,[1]Габариты!$A:$I,9,0),"") -> Основной ассортимент | AB39: =IFERROR(VLOOKUP(D:D,[1]Габариты!$A:$D,4,0),"") -> КОМОДЫ | AC39: =D39 -> 4041 | AD39: =C39 -> FBO
A40: Комод Индиго Дуб Крафт Золотой | C40: FBO | D40: 4042 | E40: 23 | H40: 2521897953005 | I40: 3521897953105 | J40: 5520897927528 | N40: L4042 | O40: 1103015578 | P40: 1103015581 | T40: E4042 | U40: 1597536850 | V40: 1597536850 | X40: L4042 | AA40: =IFERROR(VLOOKUP(D:D,[1]Габариты!$A:$I,9,0),"") -> Основной ассортимент | AB40: =IFERROR(VLOOKUP(D:D,[1]Габариты!$A:$D,4,0),"") -> КОМОДЫ | AC40: =D40 -> 4042 | AD40: =C40 -> FBO
...
